Workbook

Sheet Povzetek
A1: File Name | B1: Vozil | D1: Halucinacija | F1: Izgubil os | I1: Oddaljene osi | K1: Zamik osi | M1: Napaka rekons. | O1: Rocna napaka | Q1: Kratek signal | S1: SiWIM napaka | V1: AI OK | X1: Komentar
A2: FFH_T.txt | B2: 17 | V2: =B2 -> 17 | W2: =V2/B2 -> 1 | X2: Hevristika pravilno popravila vsa vozila, popolno ujemanje z AI
A3: FFM_T.txt | B3: 3 | V3: 3 | W3: =V3/B3 -> 1 | X3: Rocni popravki vsi OK, popolno ujemanje z AI
A4: FTT_T.txt | B4: 177 | V4: 177 | W4: =V4/B4 -> 1 | X4: Hevristika pravilno popravila vsa vozila, popolno ujemanje z AI
A5: FFH_F.txt | B5: 5 | D5: 1 | E5: =I5/B5 -> 0.2 | I5: 1 | J5: =I5/B5 -> 0.2 | V5: =B5-D5 -> 4 | W5: =V5/B5 -> 0.8
A6: FFM_F.txt | B6: 28 | D6: 2 | E6: =D6/B6 -> 0.071428571 | F6: 6 | G6: =F6/B6 -> 0.21428571 | K6: 18 | L6: =K6/B6 -> 0.64285714 | O6: 3 | P6: =O6/B6 -> 0.10714286 | Q6: 3 | R6: =Q6/B6 -> 0.10714286 | V6: =B6-D6-(F6) -> 20 | W6: =V6/B6 -> 0.71428571
A7: FTT_F.txt | B7: 183 | D7: =FTT_F!E187 -> 3 | E7: =D7/B7 -> 0.016393443 | F7: =FTT_F!C187 -> 103 | G7: =F7/B7 -> 0.56284153 | I7: =FTT_F!D187 -> 1 | J7: =I7/B7 -> 0.0054644809 | K7: =FTT_F!B187 -> 52 | L7: =K7/B7 -> 0.28415301 | M7: =FTT_F!F187 -> 25 | N7: =M7/B7 -> 0.13661202 | O7: =FTT_F!G187 -> 5 | P7: =O7/B7 -> 0.027322404 | Q7: =FTT_F!H187 -> 2 | R7: =Q7/B7 -> 0.010928962 | V7: =B7-D7-(F7-M7-O7) -> 107 | W7: =V7/B7 -> 0.58469945
A8: TFH_F.txt | B8: 42 | I8: 1 | J8: =I8/B8 -> 0.023809524 | K8: 42 | L8: =K8/B8 -> 1 | V8: =B8 -> 42 | W8: =V8/B8 -> 1 | X8: Napacna rekonstrukcija in popravek s hevristiko
A9: TTT_F.txt | B9: 157 | D9: =TTT_F!E161 -> 4 | E9: =D9/B9 -> 0.025477707 | F9: =TTT_F!D161 -> 47 | G9: =F9/B9 -> 0.29936306 | I9: =TTT_F!C161 -> 40 | J9: =I9/B9 -> 0.25477707 | K9: =TTT_F!B161 -> 28 | L9: =K9/B9 -> 0.17834395 | Q9: =TTT_F!H161 -> 15 | R9: =Q9/B9 -> 0.095541401 | S9: =TTT_F!F161 -> 21 | T9: =S9/B9 -> 0.13375796 | V9: =B9-D9-F9 -> 106 | W9: =V9/B9 -> 0.67515924
B11: =SUM(B5:B9) -> 415 | D11: =SUM(D5:D9) -> 10 | E11: =D11/B11 -> 0.024096386 | F11: =SUM(F5:F9) -> 156 | G11: =F11/B11 -> 0.37590361 | Q11: =SUM(Q5:Q9) -> 20 | R11: =Q11/B11 -> 0.048192771 | V11: =SUM(V5:V9) -> 279 | W11: =V11/B11 -> 0.67228916

Sheet FFH_T
A1: File Name | B1: Hevristika
A2: 22182_122_FFH_T.png | B2: X
A3: 38386_113_FFH_T.png | B3: X
A4: 53138_113_FFH_T.png | B4: X
A5: 80879_1111_FFH_T.png | B5: X
A6: 103772_4_FFH_T.png | B6: X
A7: 104004_1211_FFH_T.png | B7: X
A8: 125950_22_FFH_T.png | B8: X
A9: 155185_122_FFH_T.png | B9: X
A10: 156521_122_FFH_T.png | B10: X
A11: 181229_122_FFH_T.png | B11: X
A12: 184666_1111_FFH_T.png | B12: X
... A18: 214136_122_FFH_T.png | B18: X

Sheet FFM_T
A1: File Name
A2: 159640_1211_FFM_T.png
A3: 170921_1211_FFM_T.png
A4: 204397_122_FFM_T.png

Sheet FTT_T
A1: File Name
A2: 340_113_FTT_T.png
A3: 870_113_FTT_T.png
A4: 1229_122_FTT_T.png
A5: 2004_12_FTT_T.png
A6: 2303_113_FTT_T.png
A7: 2721_113_FTT_T.png
A8: 6099_113_FTT_T.png
A9: 6741_113_FTT_T.png
A10: 6881_122_FTT_T.png
A11: 10446_113_FTT_T.png
A12: 10469_1211_FTT_T.png
... A178: 246287_1211_FTT_T.png

Sheet FFH_F
A1: File Name | B1: Komentar | C1: Dodatno
A2: 53646_22_FFH_F.png | B2: Vozili blizu
A3: 149097_122_FFH_F.png | B3: Vozili blizu
A4: 156798_22_FFH_F.png | B4: Izgubil prvo v 22
A5: 187985_111_FFH_F.png | B5: Haluciniral | C5: Slaba slika
A6: 241877_122_FFH_F.png | B6: Oddaljena os

Sheet FFM_F
A1: File Name | B1: Zamik osi | C1: Halucinacija | D1: Rocna napaka | E1: Izgubil os | F1: Kratek signal | G1: Ostalo
A2: 9868_112_FFM_F.png | B2: X
A3: 10351_122_FFM_F.png | C3: X
A4: 39004_1211_FFM_F.png | D4: X
A5: 43452_1211_FFM_F.png | B5: X
A6: 43916_1211_FFM_F.png | B6: X
A7: 56916_1211_FFM_F.png | B7: X
A8: 63164_113_FFM_F.png | B8: X | E8: X
A9: 79108_112_FFM_F.png | C9: X
A10: 98612_1211_FFM_F.png | B10: X
A11: 106148_1211_FFM_F.png | B11: X
A12: 115285_1211_FFM_F.png | B12: X
A13: 123518_1212_FFM_F.png | E13: X | G13: Tezek primer, vozilo cez rob pasu
A14: 141757_122_FFM_F.png | B14: X
A15: 158290_122_FFM_F.png | D15: X
A16: 179477_122_FFM_F.png | B16: X
A17: 189253_122_FFM_F.png
A18: 189719_122_FFM_F.png | B18: X
A19: 195393_122_FFM_F.png | B19: X
A20: 200163_122_FFM_F.png | E20: X
A21: 201539_1111_FFM_F.png | E21: X | F21: X | G21: Zelo lahka os avtomobila tik za kemperjem
A22: 207544_122_FFM_F.png | B22: X
A23: 211549_1212_FFM_F.png | B23: X
A24: 216478_1211_FFM_F.png | E24: X | F24: X | G24: Lahka os praznega priklopnika
A25: 217821_1212_FFM_F.png | B25: X | D25: X
A26: 221277_123_FFM_F.png | B26: X
A27: 223271_1211_FFM_F.png | E27: X | F27: X | G27: Lahka os praznega priklopnika
A28: 241723_122_FFM_F.png | B28: X
A29: 242519_122_FFM_F.png | B29: X

Sheet FTT_F
A1: File Name | B1: Zamik osi | C1: Izgubil os | D1: Oddaljena os | E1: Halucinacija | F1: Napak rekon. | G1: Rocna napaka | H1: Kratek signal | I1: Ostalo
A2: 198_12_FTT_F.png | B2: X | F2: X
A3: 1105_112_FTT_F.png | F3: X
A4: 1294_113_FTT_F.png | C4: X
A5: 1686_113_FTT_F.png | F5: X
A6: 2013_113_FTT_F.png | B6: X | C6: X
A7: 2017_113_FTT_F.png | C7: X
A8: 2291_113_FTT_F.png | B8: X
A9: 2367_12_FTT_F.png | F9: X
A10: 2703_113_FTT_F.png | B10: X
A11: 3436_12_FTT_F.png | B11: X
A12: 3895_113_FTT_F.png | C12: X
A13: 4070_12_FTT_F.png | B13: X
A14: 4248_112_FTT_F.png | F14: X
A15: 4378_1211_FTT_F.png | B15: X
A16: 4770_12_FTT_F.png | B16: X | C16: X
A17: 4774_113_FTT_F.png | C17: X
A18: 5188_12_FTT_F.png | B18: X
A19: 6066_113_FTT_F.png | C19: X
A20: 6388_113_FTT_F.png | C20: X
A21: 6391_113_FTT_F.png | C21: X
A22: 6571_122_FTT_F.png | C22: X
A23: 6711_112_FTT_F.png | C23: X
A24: 8109_113_FTT_F.png | C24: X
A25: 8639_122_FTT_F.png | B25: X
A26: 10136_112_FTT_F.png | C26: X
A27: 10184_113_FTT_F.png | C27: X
A28: 11023_112_FTT_F.png | C28: X | G28: X
A29: 11179_113_FTT_F.png | C29: X
A30: 11634_113_FTT_F.png | C30: X
A31: 11836_113_FTT_F.png | B31: X
A32: 13181_112_FTT_F.png | C32: X
A33: 14080_113_FTT_F.png | C33: X
A34: 15268_112_FTT_F.png | G34: X
A35: 15369_112_FTT_F.png | C35: X
A36: 15999_113_FTT_F.png | C36: X
A37: 16006_112_FTT_F.png | C37: X | G37: X
A38: 16105_113_FTT_F.png | E38: X | G38: X
A39: 16163_113_FTT_F.png | C39: X
A40: 17265_113_FTT_F.png | C40: X
...

Sheet TFH_F
A1: File Name | B1: Zamik osi | C1: Oddaljena os
A2: 294_11_TFH_F.png | B2: X
A3: 348_11_TFH_F.png | B3: X
A4: 567_11_TFH_F.png | B4: X
A5: 798_11_TFH_F.png | B5: X
A6: 1882_11_TFH_F.png | B6: X
A7: 1885_11_TFH_F.png | B7: X
A8: 1900_11_TFH_F.png | B8: X
A9: 1963_11_TFH_F.png | B9: X
A10: 2027_11_TFH_F.png | B10: X
A11: 2256_11_TFH_F.png | B11: X
A12: 2487_11_TFH_F.png | B12: X
A13: 2645_11_TFH_F.png | B13: X
... A19: 3880_11_TFH_F.png | B19: X
A20: 3956_11_TFH_F.png | B20: X | C20: X
A21: 4310_11_TFH_F.png | B21: X
A22: 4787_11_TFH_F.png | B22: X
A23: 4933_11_TFH_F.png | B23: X
A24: 5020_11_TFH_F.png | B24: X
A25: 5035_11_TFH_F.png | B25: X
A26: 5257_11_TFH_F.png | B26: X
A27: 6005_11_TFH_F.png | B27: X
A28: 6415_11_TFH_F.png | B28: X
A29: 6509_11_TFH_F.png | B29: X
A30: 6710_11_TFH_F.png | B30: X
A31: 7772_11_TFH_F.png | B31: X
A32: 7912_11_TFH_F.png | B32: X
... A43: 13153_11_TFH_F.png | B43: X

Sheet TTT_F
A1: File Name | B1: Zamik osi | C1: Oddaljena os | D1: Izgubljena os | E1: Halucinacija | F1: SiWIM napaka | G1: Napaka pregleda | H1: Kratek signal | I1: Komentar
A2: 482_113_TTT_F.png | C2: X
A3: 1327_113_TTT_F.png | F3: X | G3: X
A4: 1905_11_TTT_F.png | B4: X
A5: 2558_11_TTT_F.png | C5: X
A6: 2903_113_TTT_F.png | C6: X
A7: 4219_113_TTT_F.png | C7: X
A8: 4862_122_TTT_F.png | B8: X
A9: 4993_1211_TTT_F.png | D9: X
A10: 5891_2222_TTT_F.png | D10: X | I10: Zelo lahki osi med dvema tezjima paroma
A11: 7097_11_TTT_F.png | C11: X
A12: 8169_11_TTT_F.png | F12: X | G12: X
A13: 9578_113_TTT_F.png | C13: X
A14: 9713_11_TTT_F.png | F14: X | G14: X
A15: 10256_1211_TTT_F.png | D15: X
A16: 10493_123_TTT_F.png | D16: X
A17: 10502_113_TTT_F.png | D17: X | I17: Mora tudi ni izgubljena - polpriklopnik je lahek
A18: 10691_11_TTT_F.png | C18: X
A19: 11140_11_TTT_F.png | C19: X
A20: 11594_113_TTT_F.png | F20: X | G20: X
A21: 12740_112_TTT_F.png | F21: X | G21: X
A22: 13486_11_TTT_F.png | C22: X
A23: 13530_113_TTT_F.png | F23: X | G23: X
A24: 16116_113_TTT_F.png | E24: X
A25: 17242_113_TTT_F.png | B25: X
A26: 18013_113_TTT_F.png | B26: X
A27: 18398_113_TTT_F.png | F27: X | G27: X
A28: 18794_122_TTT_F.png | B28: X
A29: 19619_113_TTT_F.png | D29: X
A30: 20711_122_TTT_F.png | B30: X
A31: 21017_122_TTT_F.png | D31: X
A32: 21142_113_TTT_F.png | C32: X
A33: 21387_113_TTT_F.png | D33: X
A34: 22133_113_TTT_F.png | D34: X
A35: 22347_113_TTT_F.png | F35: X | G35: X
A36: 22755_113_TTT_F.png | D36: X
A37: 22771_113_TTT_F.png | C37: X
A38: 23360_121_TTT_F.png | B38: X
A39: 24479_112_TTT_F.png | F39: X | G39: X
A40: 24883_1211_TTT_F.png | B40: X
...
